{"uuid": "cf5dd12e-4945-483b-a2b8-f22c5fc6d5ba", "children": ["8262c5db-d1dd-4641-a000-3205e3530a33"], "befores": [{"name": "browser", "status": "broken", "statusDetails": {"message": "selenium.common.exceptions.WebDriverException: Message: 'chromedriver' executable needs to be in PATH. Please see https://sites.google.com/a/chromium.org/chromedriver/home\n\n", "trace": "  File \"/usr/local/lib/python3.9/site-packages/pluggy/callers.py\", line 187, in _multicall\n    res = hook_impl.function(*args)\n  File \"/usr/local/lib/python3.9/site-packages/_pytest/fixtures.py\", line 964, in pytest_fixture_setup\n    result = call_fixture_func(fixturefunc, request, kwargs)\n  File \"/usr/local/lib/python3.9/site-packages/_pytest/fixtures.py\", line 788, in call_fixture_func\n    res = next(it)\n  File \"/example_ui_tests/conftest.py\", line 44, in browser\n    browser = webdriver.Chrome()\n  File \"/usr/local/lib/python3.9/site-packages/selenium/webdriver/chrome/webdriver.py\", line 73, in __init__\n    self.service.start()\n  File \"/usr/local/lib/python3.9/site-packages/selenium/webdriver/common/service.py\", line 81, in start\n    raise WebDriverException(\n"}, "steps": [{"name": "Запускаем браузер", "status": "broken", "statusDetails": {"message": "selenium.common.exceptions.WebDriverException: Message: 'chromedriver' executable needs to be in PATH. Please see https://sites.google.com/a/chromium.org/chromedriver/home\n\n", "trace": "  File \"/example_ui_tests/conftest.py\", line 44, in browser\n    browser = webdriver.Chrome()\n  File \"/usr/local/lib/python3.9/site-packages/selenium/webdriver/chrome/webdriver.py\", line 73, in __init__\n    self.service.start()\n  File \"/usr/local/lib/python3.9/site-packages/selenium/webdriver/common/service.py\", line 81, in start\n    raise WebDriverException(\n"}, "start": 1608719812996, "stop": 1608719813000}], "start": 1608719812995, "stop": 1608719813004}], "start": 1608719812995, "stop": 1608719813222}